Workbook
Name Peso_1: 'Monte Carlo'!$B$9
Name Peso_2: 'Monte Carlo'!$B$10
Name Peso_3: 'Monte Carlo'!$B$11
Name Peso_4: 'Monte Carlo'!$B$12

Sheet Info
A1: Ideias a ser consideradas
A2: 1 | B2: Construção do índice de força da seleção | L2: FC 26 Player Ratings Reveal
B3: • | C3: Força do elenco: média das notas dos jogadores
C4: FC 26 Player Ratings Reveal | I4: World Football Elo Ratings
C5: Jogadores - FC 26 - 18 de mar. de 2026 | SoFIFA
B6: • | C6: Comissão técnica
C7: Avaliar o treinador: se teve alguma conquista e quanto tempo com a seleção
B8: • | C8: Momento da seleção
C9: analisar os últimos jogos e ver se ganhou, perdeu, no de gols, posição
A10: 2 | B10: Análise dos times e possíveis resultados
B11: Quem venceu? Quem perdeu? Empate?
B12: Número de gols
A13: 3 | B13: Probabilidades para os jogos
A14: 4 | B14: Simulação de vários cenários

Sheet Seleções
A1: id | B1: Seleção | C1: Código | D1: Grupo | E1: Média dos jogadores | F1: Comissão Técnica | G1: Fifa Score | H1: Elo Rating | I1: FS_Norm | J1: ER_norm
A2: 1 | B2: Mexico | C2: MEX | D2: A | E2: =AVERAGEIFS(Tabela11[Nota],Tabela11[Seleção],teams[[#This Row],[Seleção]]) -> 74.230769 | F2: =_xlfn.XLOOKUP(teams[[#This Row],[Seleção]],Comissão!$B$2:$B$49,Comissão!$H$2:$H$49,_xleta.N,0,1) -> 76.083333 | G2: 1681.03 | H2: 1858 | I2: =teams[[#This Row],[Fifa Score]]/20 -> 84.0515 | J2: =(teams[[#This Row],[Elo Rating]]/20)*0.9 -> 83.61 | L2: Jogadores | M2: =E54 -> 72.120119 | O2: Desvio padrão Média dos jogadores | S2: =_xlfn.STDEV.S(teams[Média dos jogadores]) -> 4.7664784
A3: 2 | B3: South Africa | C3: RSA | D3: A | E3: =AVERAGEIFS(Tabela11[Nota],Tabela11[Seleção],teams[[#This Row],[Seleção]]) -> 69.695652 | F3: =_xlfn.XLOOKUP(teams[[#This Row],[Seleção]],Comissão!$B$2:$B$49,Comissão!$H$2:$H$49,_xleta.N,0,1) -> 48.366667 | G3: 1429.73 | H3: 1524 | I3: =teams[[#This Row],[Fifa Score]]/20 -> 71.4865 | J3: =(teams[[#This Row],[Elo Rating]]/20)*0.9 -> 68.58 | L3: Comissão | M3: =F54 -> 62.554514 | O3: Desvio padrão Comissão Técnica | S3: =_xlfn.STDEV.S(teams[Comissão Técnica]) -> 19.486551
A4: 3 | B4: South Korea | C4: KOR | D4: A | E4: =AVERAGEIFS(Tabela11[Nota],Tabela11[Seleção],teams[[#This Row],[Seleção]]) -> 69.384615 | F4: =_xlfn.XLOOKUP(teams[[#This Row],[Seleção]],Comissão!$B$2:$B$49,Comissão!$H$2:$H$49,_xleta.N,0,1) -> 67.9875 | G4: 1588.66 | H4: 1752 | I4: =teams[[#This Row],[Fifa Score]]/20 -> 79.433 | J4: =(teams[[#This Row],[Elo Rating]]/20)*0.9 -> 78.84 | L4: FifaScore | M4: =I54 -> 78.990229 | O4: Desvio padrão FS_Norm | S4: =_xlfn.STDEV.S(teams[FS_Norm]) -> 7.8329911
A5: 4 | B5: Czechia | C5: CZE | D5: A | E5: =AVERAGEIFS(Tabela11[Nota],Tabela11[Seleção],teams[[#This Row],[Seleção]]) -> 70.695652 | F5: =_xlfn.XLOOKUP(teams[[#This Row],[Seleção]],Comissão!$B$2:$B$49,Comissão!$H$2:$H$49,_xleta.N,0,1) -> 28.283333 | G5: 1501.38 | H5: 1726 | I5: =teams[[#This Row],[Fifa Score]]/20 -> 75.069 | J5: =(teams[[#This Row],[Elo Rating]]/20)*0.9 -> 77.67 | L5: EloRating | M5: =J54 -> 80.196563 | O5: Desvio padrão ER_Norm | S5: =_xlfn.STDEV.S(teams[ER_norm]) -> 7.9288405
A6: 5 | B6: Canada | C6: CAN | D6: B | E6: =AVERAGEIFS(Tabela11[Nota],Tabela11[Seleção],teams[[#This Row],[Seleção]]) -> 68.769231 | F6: =_xlfn.XLOOKUP(teams[[#This Row],[Seleção]],Comissão!$B$2:$B$49,Comissão!$H$2:$H$49,_xleta.N,0,1) -> 69.225 | G6: 1556.48 | H6: 1784 | I6: =teams[[#This Row],[Fifa Score]]/20 -> 77.824 | J6: =(teams[[#This Row],[Elo Rating]]/20)*0.9 -> 80.28 | L6: Média Geral | M6: =AVERAGE(M2:M5) -> 73.465356
A7: 6 | B7: Bosnia-Herzegovina | C7: BIH | D7: B | E7: =AVERAGEIFS(Tabela11[Nota],Tabela11[Seleção],teams[[#This Row],[Seleção]]) -> 68 | F7: =_xlfn.XLOOKUP(teams[[#This Row],[Seleção]],Comissão!$B$2:$B$49,Comissão!$H$2:$H$49,_xleta.N,0,1) -> 71.7 | G7: 1385.84 | H7: 1594 | I7: =teams[[#This Row],[Fifa Score]]/20 -> 69.292 | J7: =(teams[[#This Row],[Elo Rating]]/20)*0.9 -> 71.73
A8: 7 | B8: Qatar | C8: QAT | D8: B | E8: =AVERAGEIFS(Tabela11[Nota],Tabela11[Seleção],teams[[#This Row],[Seleção]]) -> 66.4375 | F8: =_xlfn.XLOOKUP(teams[[#This Row],[Seleção]],Comissão!$B$2:$B$49,Comissão!$H$2:$H$49,_xleta.N,0,1) -> 33.516667 | G8: 1454.96 | H8: 1425 | I8: =teams[[#This Row],[Fifa Score]]/20 -> 72.748 | J8: =(teams[[#This Row],[Elo Rating]]/20)*0.9 -> 64.125
A9: 8 | B9: Switzerland | C9: SUI | D9: B | E9: =AVERAGEIFS(Tabela11[Nota],Tabela11[Seleção],teams[[#This Row],[Seleção]]) -> 65.846154 | F9: =_xlfn.XLOOKUP(teams[[#This Row],[Seleção]],Comissão!$B$2:$B$49,Comissão!$H$2:$H$49,_xleta.N,0,1) -> 57.7 | G9: 1649.4 | H9: 1889 | I9: =teams[[#This Row],[Fifa Score]]/20 -> 82.47 | J9: =(teams[[#This Row],[Elo Rating]]/20)*0.9 -> 85.005
A10: 9 | B10: Brazil | C10: BRA | D10: C | E10: =AVERAGEIFS(Tabela11[Nota],Tabela11[Seleção],teams[[#This Row],[Seleção]]) -> 71.083333 | F10: =_xlfn.XLOOKUP(teams[[#This Row],[Seleção]],Comissão!$B$2:$B$49,Comissão!$H$2:$H$49,_xleta.N,0,1) -> 46.279167 | G10: 1761.16 | H10: 1984 | I10: =teams[[#This Row],[Fifa Score]]/20 -> 88.058 | J10: =(teams[[#This Row],[Elo Rating]]/20)*0.9 -> 89.28
A11: 10 | B11: Morocco | C11: MAR | D11: C | E11: =AVERAGEIFS(Tabela11[Nota],Tabela11[Seleção],teams[[#This Row],[Seleção]]) -> 74.62069 | F11: =_xlfn.XLOOKUP(teams[[#This Row],[Seleção]],Comissão!$B$2:$B$49,Comissão!$H$2:$H$49,_xleta.N,0,1) -> 38.570833 | G11: 1755.87 | H11: 1821 | I11: =teams[[#This Row],[Fifa Score]]/20 -> 87.7935 | J11: =(teams[[#This Row],[Elo Rating]]/20)*0.9 -> 81.945
A12: 11 | B12: Haiti | C12: HAI | D12: C | E12: =AVERAGEIFS(Tabela11[Nota],Tabela11[Seleção],teams[[#This Row],[Seleção]]) -> 67.36 | F12: =_xlfn.XLOOKUP(teams[[#This Row],[Seleção]],Comissão!$B$2:$B$49,Comissão!$H$2:$H$49,_xleta.N,0,1) -> 62.366667 | G12: 1291.71 | H12: 1532 | I12: =teams[[#This Row],[Fifa Score]]/20 -> 64.5855 | J12: =(teams[[#This Row],[Elo Rating]]/20)*0.9 -> 68.94
A13: 12 | B13: Scotland | C13: SCO | D13: C | E13: =AVERAGEIFS(Tabela11[Nota],Tabela11[Seleção],teams[[#This Row],[Seleção]]) -> 73.269231 | F13: =_xlfn.XLOOKUP(teams[[#This Row],[Seleção]],Comissão!$B$2:$B$49,Comissão!$H$2:$H$49,_xleta.N,0,1) -> 57.7 | G13: 1498.35 | H13: 1767 | I13: =teams[[#This Row],[Fifa Score]]/20 -> 74.9175 | J13: =(teams[[#This Row],[Elo Rating]]/20)*0.9 -> 79.515
A14: 13 | B14: USA | C14: USA | D14: D | E14: =AVERAGEIFS(Tabela11[Nota],Tabela11[Seleção],teams[[#This Row],[Seleção]]) -> 74.153846 | F14: =_xlfn.XLOOKUP(teams[[#This Row],[Seleção]],Comissão!$B$2:$B$49,Comissão!$H$2:$H$49,_xleta.N,0,1) -> 65.5125 | G14: 1673.13 | H14: 1721 | I14: =teams[[#This Row],[Fifa Score]]/20 -> 83.6565 | J14: =(teams[[#This Row],[Elo Rating]]/20)*0.9 -> 77.445
A15: 14 | B15: Paraguay | C15: PAR | D15: D | E15: =AVERAGEIFS(Tabela11[Nota],Tabela11[Seleção],teams[[#This Row],[Seleção]]) -> 71.269231 | F15: =_xlfn.XLOOKUP(teams[[#This Row],[Seleção]],Comissão!$B$2:$B$49,Comissão!$H$2:$H$49,_xleta.N,0,1) -> 52.75 | G15: 1503.5 | H15: 1833 | I15: =teams[[#This Row],[Fifa Score]]/20 -> 75.175 | J15: =(teams[[#This Row],[Elo Rating]]/20)*0.9 -> 82.485
A16: 15 | B16: Australia | C16: AUS | D16: D | E16: =AVERAGEIFS(Tabela11[Nota],Tabela11[Seleção],teams[[#This Row],[Seleção]]) -> 67.777778 | F16: =_xlfn.XLOOKUP(teams[[#This Row],[Seleção]],Comissão!$B$2:$B$49,Comissão!$H$2:$H$49,_xleta.N,0,1) -> 51.5125 | G16: 1580.67 | H16: 1783 | I16: =teams[[#This Row],[Fifa Score]]/20 -> 79.0335 | J16: =(teams[[#This Row],[Elo Rating]]/20)*0.9 -> 80.235
A17: 16 | B17: Turkiye | C17: TUR | D17: D | E17: =AVERAGEIFS(Tabela11[Nota],Tabela11[Seleção],teams[[#This Row],[Seleção]]) -> 76.344828 | F17: =_xlfn.XLOOKUP(teams[[#This Row],[Seleção]],Comissão!$B$2:$B$49,Comissão!$H$2:$H$49,_xleta.N,0,1) -> 90.366667 | G17: 1599.04 | H17: 1902 | I17: =teams[[#This Row],[Fifa Score]]/20 -> 79.952 | J17: =(teams[[#This Row],[Elo Rating]]/20)*0.9 -> 85.59
A18: 17 | B18: Germany | C18: GER | D18: E | E18: =AVERAGEIFS(Tabela11[Nota],Tabela11[Seleção],teams[[#This Row],[Seleção]]) -> 80.423077 | F18: =_xlfn.XLOOKUP(teams[[#This Row],[Seleção]],Comissão!$B$2:$B$49,Comissão!$H$2:$H$49,_xleta.N,0,1) -> 99.7 | G18: 1730.37 | H18: 1923 | I18: =teams[[#This Row],[Fifa Score]]/20 -> 86.5185 | J18: =(teams[[#This Row],[Elo Rating]]/20)*0.9 -> 86.535
... A31: 30 | B31: Cabo Verde | C31: CPV | D31: H | E31: =AVERAGEIFS(Tabela11[Nota],Tabela11[Seleção],teams[[#This Row],[Seleção]]) -> 69.653846 | F31: =_xlfn.XLOOKUP(teams[[#This Row],[Seleção]],Comissão!$B$2:$B$49,Comissão!$H$2:$H$49,_xleta.N,0,1) -> 57.7 | G31: 1366.13 | H31: 1549 | I31: =teams[[#This Row],[Fifa Score]]/20 -> 68.3065 | J31: =(teams[[#This Row],[Elo Rating]]/20)*0.9 -> 69.705
A32: 31 | B32: Saudi Arabia | C32: KSA | D32: H | E32: =AVERAGEIFS(Tabela11[Nota],Tabela11[Seleção],teams[[#This Row],[Seleção]]) -> 64.225806 | F32: =_xlfn.XLOOKUP(teams[[#This Row],[Seleção]],Comissão!$B$2:$B$49,Comissão!$H$2:$H$49,_xleta.N,0,1) -> 39.704167 | G32: 1421.43 | H32: 1568 | I32: =teams[[#This Row],[Fifa Score]]/20 -> 71.0715 | J32: =(teams[[#This Row],[Elo Rating]]/20)*0.9 -> 70.56 | L32: Desvio padrão Média dos jogadores
A33: 32 | B33: Uruguay | C33: URU | D33: H | E33: =AVERAGEIFS(Tabela11[Nota],Tabela11[Seleção],teams[[#This Row],[Seleção]]) -> 74.848485 | F33: =_xlfn.XLOOKUP(teams[[#This Row],[Seleção]],Comissão!$B$2:$B$49,Comissão!$H$2:$H$49,_xleta.N,0,1) -> 56.4625 | G33: 1673.07 | H33: 1892 | I33: =teams[[#This Row],[Fifa Score]]/20 -> 83.6535 | J33: =(teams[[#This Row],[Elo Rating]]/20)*0.9 -> 85.14 | L33: Desvio padrão Comissão Técnica
A34: 33 | B34: France | C34: FRA | D34: I | E34: =AVERAGEIFS(Tabela11[Nota],Tabela11[Seleção],teams[[#This Row],[Seleção]]) -> 81.8 | F34: =_xlfn.XLOOKUP(teams[[#This Row],[Seleção]],Comissão!$B$2:$B$49,Comissão!$H$2:$H$49,_xleta.N,0,1) -> 90.366667 | G34: 1877.32 | H34: 2082 | I34: =teams[[#This Row],[Fifa Score]]/20 -> 93.866 | J34: =(teams[[#This Row],[Elo Rating]]/20)*0.9 -> 93.69 | L34: Desvio padrão FifaScore
A35: 34 | B35: Senegal | C35: SEN | D35: I | E35: =AVERAGEIFS(Tabela11[Nota],Tabela11[Seleção],teams[[#This Row],[Seleção]]) -> 73.607143 | F35: =_xlfn.XLOOKUP(teams[[#This Row],[Seleção]],Comissão!$B$2:$B$49,Comissão!$H$2:$H$49,_xleta.N,0,1) -> 89.8 | G35: 1688.99 | H35: 1879 | I35: =teams[[#This Row],[Fifa Score]]/20 -> 84.4495 | J35: =(teams[[#This Row],[Elo Rating]]/20)*0.9 -> 84.555 | L35: Desvio padrão EloRating
A36: 35 | B36: Iraq | C36: IRQ | D36: I | E36: =AVERAGEIFS(Tabela11[Nota],Tabela11[Seleção],teams[[#This Row],[Seleção]]) -> 65.071429 | F36: =_xlfn.XLOOKUP(teams[[#This Row],[Seleção]],Comissão!$B$2:$B$49,Comissão!$H$2:$H$49,_xleta.N,0,1) -> 55.6125 | G36: 1447.14 | H36: 1607 | I36: =teams[[#This Row],[Fifa Score]]/20 -> 72.357 | J36: =(teams[[#This Row],[Elo Rating]]/20)*0.9 -> 72.315
A37: 36 | B37: Norway | C37: NOR | D37: I | E37: =AVERAGEIFS(Tabela11[Nota],Tabela11[Seleção],teams[[#This Row],[Seleção]]) -> 73.041667 | F37: =_xlfn.XLOOKUP(teams[[#This Row],[Seleção]],Comissão!$B$2:$B$49,Comissão!$H$2:$H$49,_xleta.N,0,1) -> 67.033333 | G37: 1550.94 | H37: 1912 | I37: =teams[[#This Row],[Fifa Score]]/20 -> 77.547 | J37: =(teams[[#This Row],[Elo Rating]]/20)*0.9 -> 86.04
A38: 37 | B38: Argentina | C38: ARG | D38: J | E38: =AVERAGEIFS(Tabela11[Nota],Tabela11[Seleção],teams[[#This Row],[Seleção]]) -> 77.965517 | F38: =_xlfn.XLOOKUP(teams[[#This Row],[Seleção]],Comissão!$B$2:$B$49,Comissão!$H$2:$H$49,_xleta.N,0,1) -> 99.7 | G38: 1874.81 | H38: 2113 | I38: =teams[[#This Row],[Fifa Score]]/20 -> 93.7405 | J38: =(teams[[#This Row],[Elo Rating]]/20)*0.9 -> 95.085
A39: 38 | B39: Algeria | C39: ALG | D39: J | E39: =AVERAGEIFS(Tabela11[Nota],Tabela11[Seleção],teams[[#This Row],[Seleção]]) -> 71.481481 | F39: =_xlfn.XLOOKUP(teams[[#This Row],[Seleção]],Comissão!$B$2:$B$49,Comissão!$H$2:$H$49,_xleta.N,0,1) -> 76.366667 | G39: 1564.26 | H39: 1743 | I39: =teams[[#This Row],[Fifa Score]]/20 -> 78.213 | J39: =(teams[[#This Row],[Elo Rating]]/20)*0.9 -> 78.435
A40: 39 | B40: Austria | C40: AUT | D40: J | E40: =AVERAGEIFS(Tabela11[Nota],Tabela11[Seleção],teams[[#This Row],[Seleção]]) -> 76.285714 | F40: =_xlfn.XLOOKUP(teams[[#This Row],[Seleção]],Comissão!$B$2:$B$49,Comissão!$H$2:$H$49,_xleta.N,0,1) -> 76.366667 | G40: 1593.45 | H40: 1827 | I40: =teams[[#This Row],[Fifa Score]]/20 -> 79.6725 | J40: =(teams[[#This Row],[Elo Rating]]/20)*0.9 -> 82.215
A41: 40 | B41: Jordan | C41: JOR | D41: J | E41: =AVERAGEIFS(Tabela11[Nota],Tabela11[Seleção],teams[[#This Row],[Seleção]]) -> 65.407407 | F41: =_xlfn.XLOOKUP(teams[[#This Row],[Seleção]],Comissão!$B$2:$B$49,Comissão!$H$2:$H$49,_xleta.N,0,1) -> 64.558333 | G41: 1391.45 | H41: 1690 | I41: =teams[[#This Row],[Fifa Score]]/20 -> 69.5725 | J41: =(teams[[#This Row],[Elo Rating]]/20)*0.9 -> 76.05
A42: 41 | B42: Portugal | C42: POR | D42: K | E42: =AVERAGEIFS(Tabela11[Nota],Tabela11[Seleção],teams[[#This Row],[Seleção]]) -> 80.2 | F42: =_xlfn.XLOOKUP(teams[[#This Row],[Seleção]],Comissão!$B$2:$B$49,Comissão!$H$2:$H$49,_xleta.N,0,1) -> 67.033333 | G42: 1763.83 | H42: 1984 | I42: =teams[[#This Row],[Fifa Score]]/20 -> 88.1915 | J42: =(teams[[#This Row],[Elo Rating]]/20)*0.9 -> 89.28
A43: 42 | B43: Congo | C43: COD | D43: K | E43: =AVERAGEIFS(Tabela11[Nota],Tabela11[Seleção],teams[[#This Row],[Seleção]]) -> 72.52381 | F43: =_xlfn.XLOOKUP(teams[[#This Row],[Seleção]],Comissão!$B$2:$B$49,Comissão!$H$2:$H$49,_xleta.N,0,1) -> 76.366667 | G43: 1478.35 | H43: 1655 | I43: =teams[[#This Row],[Fifa Score]]/20 -> 73.9175 | J43: =(teams[[#This Row],[Elo Rating]]/20)*0.9 -> 74.475
A44: 43 | B44: Uzbekistan | C44: UZB | D44: K | E44: =AVERAGEIFS(Tabela11[Nota],Tabela11[Seleção],teams[[#This Row],[Seleção]]) -> 68.576923 | F44: =_xlfn.XLOOKUP(teams[[#This Row],[Seleção]],Comissão!$B$2:$B$49,Comissão!$H$2:$H$49,_xleta.N,0,1) -> 49.425 | G44: 1465.34 | H44: 1727 | I44: =teams[[#This Row],[Fifa Score]]/20 -> 73.267 | J44: =(teams[[#This Row],[Elo Rating]]/20)*0.9 -> 77.715
A45: 44 | B45: Colombia | C45: COL | D45: K | E45: =AVERAGEIFS(Tabela11[Nota],Tabela11[Seleção],teams[[#This Row],[Seleção]]) -> 76.230769 | F45: =_xlfn.XLOOKUP(teams[[#This Row],[Seleção]],Comissão!$B$2:$B$49,Comissão!$H$2:$H$49,_xleta.N,0,1) -> 62.366667 | G45: 1693.09 | H45: 1975 | I45: =teams[[#This Row],[Fifa Score]]/20 -> 84.6545 | J45: =(teams[[#This Row],[Elo Rating]]/20)*0.9 -> 88.875
A46: 45 | B46: England | C46: ENG | D46: L | E46: =AVERAGEIFS(Tabela11[Nota],Tabela11[Seleção],teams[[#This Row],[Seleção]]) -> 80.342857 | F46: =_xlfn.XLOOKUP(teams[[#This Row],[Seleção]],Comissão!$B$2:$B$49,Comissão!$H$2:$H$49,_xleta.N,0,1) -> 65.229167 | G46: 1825.97 | H46: 2020 | I46: =teams[[#This Row],[Fifa Score]]/20 -> 91.2985 | J46: =(teams[[#This Row],[Elo Rating]]/20)*0.9 -> 90.9
A47: 46 | B47: Croatia | C47: CRO | D47: L | E47: =AVERAGEIFS(Tabela11[Nota],Tabela11[Seleção],teams[[#This Row],[Seleção]]) -> 75.346154 | F47: =_xlfn.XLOOKUP(teams[[#This Row],[Seleção]],Comissão!$B$2:$B$49,Comissão!$H$2:$H$49,_xleta.N,0,1) -> 71.7 | G47: 1717.07 | H47: 1930 | I47: =teams[[#This Row],[Fifa Score]]/20 -> 85.8535 | J47: =(teams[[#This Row],[Elo Rating]]/20)*0.9 -> 86.85
... A49: 48 | B49: Panama | C49: PAN | D49: L | E49: =AVERAGEIFS(Tabela11[Nota],Tabela11[Seleção],teams[[#This Row],[Seleção]]) -> 68.304348 | F49: =_xlfn.XLOOKUP(teams[[#This Row],[Seleção]],Comissão!$B$2:$B$49,Comissão!$H$2:$H$49,_xleta.N,0,1) -> 67.033333 | G49: 1540.64 | H49: 1737 | I49: =teams[[#This Row],[Fifa Score]]/20 -> 77.032 | J49: =(teams[[#This Row],[Elo Rating]]/20)*0.9 -> 78.165
G51: link | H51: link
B54: Média | E54: =AVERAGE(teams[Média dos jogadores]) -> 72.120119 | F54: =AVERAGE(teams[Comissão Técnica]) -> 62.554514 | G54: =AVERAGE(teams[Fifa Score]) -> 1579.8046 | H54: =AVERAGE(teams[Elo Rating]) -> 1782.1458 | I54: =AVERAGE(teams[FS_Norm]) -> 78.990229 | J54: =AVERAGE(teams[ER_norm]) -> 80.196563

Sheet Comissão
A1: id | B1: Seleção | C1: Treinador | D1: Longevidade (meses) - 04/26 | E1: % Vitórias | F1: % Empates | G1: % Derrotas | H1: Nota Técnica
A2: =Seleções!A2 -> 1 | B2: =Seleções!B2 -> Mexico | C2: =Treinadores!A18 -> Javier Aguirre | D2: 20 | E2: 0.6 | F2: 0.4 | G2: 0 | H2: =(((E2)*3+(F2)*1)/3)*70+(MIN(D2/24,1)*30)*0.99 -> 76.083333
A3: =Seleções!A3 -> 2 | B3: =Seleções!B3 -> South Africa | C3: =Treinadores!A16 -> Hugo Broos | D3: 60 | E3: 0.2 | F3: 0.2 | G3: 0.6 | H3: =(((E3)*3+(F3)*1)/3)*70+(MIN(D3/24,1)*30)*0.99 -> 48.366667
A4: =Seleções!A4 -> 3 | B4: =Seleções!B4 -> South Korea | C4: =Treinadores!A29 -> Myung-bo Hong | D4: 21 | E4: 0.6 | F4: 0 | G4: 0.4 | H4: =(((E4)*3+(F4)*1)/3)*70+(MIN(D4/24,1)*30)*0.99 -> 67.9875
A5: =Seleções!A5 -> 4 | B5: =Seleções!B5 -> Czechia | C5: =Treinadores!A26 -> Miroslav Koubek | D5: 4 | E5: 0.2 | F5: 0.4 | G5: 0.4 | H5: =(((E5)*3+(F5)*1)/3)*70+(MIN(D5/24,1)*30)*0.99 -> 28.283333
A6: =Seleções!A6 -> 5 | B6: =Seleções!B6 -> Canada | C6: =Treinadores!A19 -> Jesse Marsch | D6: 22 | E6: 0.4 | F6: 0.6 | G6: 0 | H6: =(((E6)*3+(F6)*1)/3)*70+(MIN(D6/24,1)*30)*0.99 -> 69.225
A7: =Seleções!A7 -> 6 | B7: =Seleções!B7 -> Bosnia-Herzegovina | C7: =Treinadores!A38 -> Sergej Barbarez | D7: 24 | E7: 0.4 | F7: 0.6 | G7: 0 | H7: =(((E7)*3+(F7)*1)/3)*70+(MIN(D7/24,1)*30)*0.99 -> 71.7
A8: =Seleções!A8 -> 7 | B8: =Seleções!B8 -> Qatar | C8: =Treinadores!A20 -> Julen Lopetegui | D8: 12 | E8: 0.2 | F8: 0.2 | G8: 0.6 | H8: =(((E8)*3+(F8)*1)/3)*70+(MIN(D8/24,1)*30)*0.99 -> 33.516667
A9: =Seleções!A9 -> 8 | B9: =Seleções!B9 -> Switzerland | C9: =Treinadores!A28 -> Murat Yakin | D9: 56 | E9: 0.2 | F9: 0.6 | G9: 0.2 | H9: =(((E9)*3+(F9)*1)/3)*70+(MIN(D9/24,1)*30)*0.99 -> 57.7
A10: =Seleções!A10 -> 9 | B10: =Seleções!B10 -> Brazil | C10: =Treinadores!A4 -> Carlo Ancelotti | D10: 11 | E10: 0.4 | F10: 0.2 | G10: 0.4 | H10: =(((E10)*3+(F10)*1)/3)*70+(MIN(D10/24,1)*30)*0.99 -> 46.279167 | O10: adicionar um bônus para o historico de titulos do treinador
A11: =Seleções!A11 -> 10 | B11: =Seleções!B11 -> Morocco | C11: =Treinadores!A27 -> Mohamed Ouahbi | D11: 1 | E11: 0.4 | F11: 0.4 | G11: 0.2 | H11: =(((E11)*3+(F11)*1)/3)*70+(MIN(D11/24,1)*30)*0.99 -> 38.570833 | O11: por exemplo o ancelotti ganhou um titulo importante ent ele tem um peso maior
A12: =Seleções!A12 -> 11 | B12: =Seleções!B12 -> Haiti | C12: =Treinadores!A42 -> Sébastien Migné | D12: 25 | E12: 0.4 | F12: 0.2 | G12: 0.4 | H12: =(((E12)*3+(F12)*1)/3)*70+(MIN(D12/24,1)*30)*0.99 -> 62.366667 | O12: rodar mais que uma simulação mudando o peso
A13: =Seleções!A13 -> 12 | B13: =Seleções!B13 -> Scotland | C13: =Treinadores!A39 -> Steve Clarke | D13: 82 | E13: 0.4 | F13: 0 | G13: 0.6 | H13: =(((E13)*3+(F13)*1)/3)*70+(MIN(D13/24,1)*30)*0.99 -> 57.7
A14: =Seleções!A14 -> 13 | B14: =Seleções!B14 -> USA | C14: =Treinadores!A25 -> Mauricio Pochettino | D14: 19 | E14: 0.6 | F14: 0 | G14: 0.4 | H14: =(((E14)*3+(F14)*1)/3)*70+(MIN(D14/24,1)*30)*0.99 -> 65.5125
A15: =Seleções!A15 -> 14 | B15: =Seleções!B15 -> Paraguay | C15: =Treinadores!A12 -> Gustavo Alfaro | D15: 20 | E15: 0.4 | F15: 0 | G15: 0.6 | H15: =(((E15)*3+(F15)*1)/3)*70+(MIN(D15/24,1)*30)*0.99 -> 52.75
A16: =Seleções!A16 -> 15 | B16: =Seleções!B16 -> Australia | C16: =Treinadores!A45 -> Tony Popovic | D16: 19 | E16: 0.4 | F16: 0 | G16: 0.6 | H16: =(((E16)*3+(F16)*1)/3)*70+(MIN(D16/24,1)*30)*0.99 -> 51.5125
A17: =Seleções!A17 -> 16 | B17: =Seleções!B17 -> Turkiye | C17: =Treinadores!A46 -> Vincenzo Montella | D17: 31 | E17: 0.8 | F17: 0.2 | G17: 0 | H17: =(((E17)*3+(F17)*1)/3)*70+(MIN(D17/24,1)*30)*0.99 -> 90.366667
A18: =Seleções!A18 -> 17 | B18: =Seleções!B18 -> Germany | C18: =Treinadores!A21 -> Julian Nagelsmann | D18: 31 | E18: 1 | F18: 0 | G18: 0 | H18: =(((E18)*3+(F18)*1)/3)*70+(MIN(D18/24,1)*30)*0.99 -> 99.7
A19: =Seleções!A19 -> 18 | B19: =Seleções!B19 -> Curaçao | C19: =Treinadores!A9 -> Fred Rutten | D19: 1 | E19: 0.2 | F19: 0.4 | G19: 0.4 | H19: =(((E19)*3+(F19)*1)/3)*70+(MIN(D19/24,1)*30)*0.99 -> 24.570833
A20: =Seleções!A20 -> 19 | B20: =Seleções!B20 -> Côte d'Ivoire | C20: =Treinadores!A7 -> Emerse Faé | D20: 2 | E20: 0.8 | F20: 0 | G20: 0.2 | H20: =(((E20)*3+(F20)*1)/3)*70+(MIN(D20/24,1)*30)*0.99 -> 58.475
A21: =Seleções!A21 -> 20 | B21: =Seleções!B21 -> Ecuador | C21: =Treinadores!A37 -> Sebastián Beccacece | D21: 20 | E21: 0.2 | F21: 0.8 | G21: 0 | H21: =(((E21)*3+(F21)*1)/3)*70+(MIN(D21/24,1)*30)*0.99 -> 57.416667
A22: =Seleções!A22 -> 21 | B22: =Seleções!B22 -> Netherlands | C22: =Treinadores!A34 -> Ronald Koeman | D22: 36 | E22: 0.6 | F22: 0.4 | G22: 0 | H22: =(((E22)*3+(F22)*1)/3)*70+(MIN(D22/24,1)*30)*0.99 -> 81.033333
A23: =Seleções!A23 -> 22 | B23: =Seleções!B23 -> Japan | C23: =Treinadores!A13 -> Hajime Moriyasu | D23: 92 | E23: 1 | F23: 0 | G23: 0 | H23: =(((E23)*3+(F23)*1)/3)*70+(MIN(D23/24,1)*30)*0.99 -> 99.7
A24: =Seleções!A24 -> 23 | B24: =Seleções!B24 -> Sweden | C24: =Treinadores!A11 -> Graham Potter | D24: 6 | E24: 0.4 | F24: 0.2 | G24: 0.4 | H24: =(((E24)*3+(F24)*1)/3)*70+(MIN(D24/24,1)*30)*0.99 -> 40.091667
A25: =Seleções!A25 -> 24 | B25: =Seleções!B25 -> Tunisia | C25: =Treinadores!A36 -> Sabri Lamouchi | D25: 3 | E25: 0.2 | F25: 0.6 | G25: 0.2 | H25: =(((E25)*3+(F25)*1)/3)*70+(MIN(D25/24,1)*30)*0.99 -> 31.7125
A26: =Seleções!A26 -> 25 | B26: =Seleções!B26 -> Belgium | C26: =Treinadores!A35 -> Rudi Garcia | D26: 15 | E26: 0.6 | F26: 0.4 | G26: 0 | H26: =(((E26)*3+(F26)*1)/3)*70+(MIN(D26/24,1)*30)*0.99 -> 69.895833
A27: =Seleções!A27 -> 26 | B27: =Seleções!B27 -> Egypt | C27: =Treinadores!A15 -> Hossam Hassan | D27: 26 | E27: 0.6 | F27: 0.2 | G27: 0.2 | H27: =(((E27)*3+(F27)*1)/3)*70+(MIN(D27/24,1)*30)*0.99 -> 76.366667
A28: =Seleções!A28 -> 27 | B28: =Seleções!B28 -> IR Iran | C28: =Treinadores!A2 -> Amir Ghalenoei | D28: 36 | E28: 0.4 | F28: 0.4 | G28: 0.2 | H28: =(((E28)*3+(F28)*1)/3)*70+(MIN(D28/24,1)*30)*0.99 -> 67.033333
A29: =Seleções!A29 -> 28 | B29: =Seleções!B29 -> New Zealand | C29: =Treinadores!A5 -> Darren Bazeley | D29: 33 | E29: 0.2 | F29: 0.2 | G29: 0.6 | H29: =(((E29)*3+(F29)*1)/3)*70+(MIN(D29/24,1)*30)*0.99 -> 48.366667
A30: =Seleções!A30 -> 29 | B30: =Seleções!B30 -> Spain | C30: =Treinadores!A23 -> Luis de la Fuente | D30: 36 | E30: 0.6 | F30: 0.4 | G30: 0 | H30: =(((E30)*3+(F30)*1)/3)*70+(MIN(D30/24,1)*30)*0.99 -> 81.033333
A31: =Seleções!A31 -> 30 | B31: =Seleções!B31 -> Cabo Verde | C31: =Treinadores!A3 -> Bubista | D31: 74 | E31: 0.2 | F31: 0.6 | G31: 0.2 | H31: =(((E31)*3+(F31)*1)/3)*70+(MIN(D31/24,1)*30)*0.99 -> 57.7
A32: =Seleções!A32 -> 31 | B32: =Seleções!B32 -> Saudi Arabia | C32: =Treinadores!A14 -> Hervé Renard | D32: 17 | E32: 0.2 | F32: 0.2 | G32: 0.6 | H32: =(((E32)*3+(F32)*1)/3)*70+(MIN(D32/24,1)*30)*0.99 -> 39.704167
A33: =Seleções!A33 -> 32 | B33: =Seleções!B33 -> Uruguay | C33: =Treinadores!A24 -> Marcelo Bielsa | D33: 23 | E33: 0.2 | F33: 0.6 | G33: 0.2 | H33: =(((E33)*3+(F33)*1)/3)*70+(MIN(D33/24,1)*30)*0.99 -> 56.4625
A34: =Seleções!A34 -> 33 | B34: =Seleções!B34 -> France | C34: =Treinadores!A6 -> Didier Deschamps | D34: 165 | E34: 0.8 | F34: 0.2 | G34: 0 | H34: =(((E34)*3+(F34)*1)/3)*70+(MIN(D34/24,1)*30)*0.99 -> 90.366667
A35: =Seleções!A35 -> 34 | B35: =Seleções!B35 -> Senegal | C35: =Treinadores!A31 -> Pape Thiaw | D35: 16 | E35: 1 | F35: 0 | G35: 0 | H35: =(((E35)*3+(F35)*1)/3)*70+(MIN(D35/24,1)*30)*0.99 -> 89.8
A36: =Seleções!A36 -> 35 | B36: =Seleções!B36 -> Iraq | C36: =Treinadores!A10 -> Graham Arnold | D36: 11 | E36: 0.6 | F36: 0 | G36: 0.4 | H36: =(((E36)*3+(F36)*1)/3)*70+(MIN(D36/24,1)*30)*0.99 -> 55.6125
A37: =Seleções!A37 -> 36 | B37: =Seleções!B37 -> Norway | C37: =Treinadores!A40 -> Ståle Solbakken | D37: 64 | E37: 0.4 | F37: 0.4 | G37: 0.2 | H37: =(((E37)*3+(F37)*1)/3)*70+(MIN(D37/24,1)*30)*0.99 -> 67.033333
A38: =Seleções!A38 -> 37 | B38: =Seleções!B38 -> Argentina | C38: =Treinadores!A22 -> Lionel Scaloni | D38: 92 | E38: 1 | F38: 0 | G38: 0 | H38: =(((E38)*3+(F38)*1)/3)*70+(MIN(D38/24,1)*30)*0.99 -> 99.7
A39: =Seleções!A39 -> 38 | B39: =Seleções!B39 -> Algeria | C39: =Treinadores!A47 -> Vladimir Petkovic | D39: 25 | E39: 0.6 | F39: 0.2 | G39: 0.2 | H39: =(((E39)*3+(F39)*1)/3)*70+(MIN(D39/24,1)*30)*0.99 -> 76.366667
A40: =Seleções!A40 -> 39 | B40: =Seleções!B40 -> Austria | C40: =Treinadores!A32 -> Ralf Rangnick | D40: 46 | E40: 0.6 | F40: 0.2 | G40: 0.2 | H40: =(((E40)*3+(F40)*1)/3)*70+(MIN(D40/24,1)*30)*0.99 -> 76.366667
...

Sheet Saldo
A1: id | B1: Seleção | C1: % Vitórias (Últimos 20) | D1: Gols Marcados (GP) | E1: Gols Sofridos (GC) | F1: Saldo de Gols (SG) | G1: Média de gols feitos | H1: Média de gols sofridos
A2: 1 | B2: Mexico | C2: 0.6 | D2: 38 | E2: 21 | F2: =D2-E2 -> 17 | G2: =D2/20 -> 1.9 | H2: =E2/20 -> 1.05
A3: 2 | B3: South Africa | C3: 0.45 | D3: 24 | E3: 22 | F3: =D3-E3 -> 2 | G3: =D3/20 -> 1.2 | H3: =E3/20 -> 1.1
A4: 3 | B4: South Korea | C4: 0.65 | D4: 45 | E4: 18 | F4: =D4-E4 -> 27 | G4: =D4/20 -> 2.25 | H4: =E4/20 -> 0.9
A5: 4 | B5: Czechia | C5: 0.5 | D5: 31 | E5: 26 | F5: =D5-E5 -> 5 | G5: =D5/20 -> 1.55 | H5: =E5/20 -> 1.3
A6: 5 | B6: Canada | C6: 0.5 | D6: 34 | E6: 28 | F6: =D6-E6 -> 6 | G6: =D6/20 -> 1.7 | H6: =E6/20 -> 1.4
A7: 6 | B7: Bosnia-Herzegovina | C7: 0.35 | D7: 22 | E7: 33 | F7: =D7-E7 -> -11 | G7: =D7/20 -> 1.1 | H7: =E7/20 -> 1.65
A8: 7 | B8: Qatar | C8: 0.55 | D8: 36 | E8: 27 | F8: =D8-E8 -> 9 | G8: =D8/20 -> 1.8 | H8: =E8/20 -> 1.35
A9: 8 | B9: Switzerland | C9: 0.45 | D9: 29 | E9: 25 | F9: =D9-E9 -> 4 | G9: =D9/20 -> 1.45 | H9: =E9/20 -> 1.25
A10: 9 | B10: Brazil | C10: 0.7 | D10: 48 | E10: 15 | F10: =D10-E10 -> 33 | G10: =D10/20 -> 2.4 | H10: =E10/20 -> 0.75
A11: 10 | B11: Morocco | C11: 0.65 | D11: 35 | E11: 14 | F11: =D11-E11 -> 21 | G11: =D11/20 -> 1.75 | H11: =E11/20 -> 0.7
A12: 11 | B12: Haiti | C12: 0.3 | D12: 19 | E12: 38 | F12: =D12-E12 -> -19 | G12: =D12/20 -> 0.95 | H12: =E12/20 -> 1.9
A13: 12 | B13: Scotland | C13: 0.4 | D13: 24 | E13: 31 | F13: =D13-E13 -> -7 | G13: =D13/20 -> 1.2 | H13: =E13/20 -> 1.55
... A49: 48 | B49: Panama | C49: 0.45 | D49: 28 | E49: 30 | F49: =D49-E49 -> -2 | G49: =D49/20 -> 1.4 | H49: =E49/20 -> 1.5

Sheet Jogos
A1: date | B1: match_number | C1: group | D1: stadium | E1: date_dt
A2: 46184 | B2: Match 1 | C2: Group A | D2: Mexico City Stadium | E2: 46184
A3: 46184 | B3: Match 2 | C3: Group A | D3: Estadio Guadalajara | E3: 46184
A4: 46185 | B4: Match 3 | C4: Group B | D4: Toronto Stadium | E4: 46185
A5: 46185 | B5: Match 4 | C5: Group D | D5: Los Angeles Stadium | E5: 46185
A6: 46186 | B6: Match 5 | C6: Group C | D6: Boston Stadium | E6: 46186
A7: 46186 | B7: Match 6 | C7: Group D | D7: BC Place Vancouver | E7: 46186
A8: 46186 | B8: Match 7 | C8: Group C | D8: New York New Jersey Stadium | E8: 46186
A9: 46186 | B9: Match 8 | C9: Group B | D9: San Francisco Bay Area Stadium | E9: 46186
A10: 46187 | B10: Match 9 | C10: Group E | D10: Philadelphia Stadium | E10: 46187
A11: 46187 | B11: Match 10 | C11: Group E | D11: Houston Stadium | E11: 46187
A12: 46187 | B12: Match 11 | C12: Group F | D12: Dallas Stadium | E12: 46187
A13: 46187 | B13: Match 12 | C13: Group F | D13: Estadio Monterrey | E13: 46187
... A105: 46222 | B105: Match 104 | C105: Winner match 101 v Winner match 102 | D105: New York New Jersey Stadium | E105: 46222

Sheet Jogadores
A1: Grupo | B1: Seleção | C1: Jogador | D1: Nota | F1: Grupo | G1: Seleção | H1: Média dos jogadores
A2: A | B2: Mexico | C2: Guillermo Ochoa | D2: 74 | F2: A | G2: Mexico | H2: =AVERAGEIFS(Tabela11[Nota],Tabela11[Seleção],G2) -> 74.230769
A3: A | B3: Mexico | C3: Carlos Acevedo | D3: 74 | F3: A | G3: South Africa | H3: =AVERAGEIFS(Tabela11[Nota],Tabela11[Seleção],G3) -> 69.695652
A4: A | B4: Mexico | C4: Raúl Rangel | D4: 76 | F4: A | G4: South Korea | H4: =AVERAGEIFS(Tabela11[Nota],Tabela11[Seleção],G4) -> 69.384615
A5: A | B5: Mexico | C5: Jesús Gallardo | D5: 77 | F5: A | G5: Czechia | H5: =AVERAGEIFS(Tabela11[Nota],Tabela11[Seleção],G5) -> 70.695652
A6: A | B6: Mexico | C6: Jorge Sánchez | D6: 73 | F6: B | G6: Canada | H6: =AVERAGEIFS(Tabela11[Nota],Tabela11[Seleção],G6) -> 68.769231
A7: A | B7: Mexico | C7: César Montes | D7: 75 | F7: B | G7: Bosnia-Herzegovina | H7: =AVERAGEIFS(Tabela11[Nota],Tabela11[Seleção],G7) -> 68
A8: A | B8: Mexico | C8: Jesús Ângulo | D8: 74 | F8: B | G8: Qatar | H8: =AVERAGEIFS(Tabela11[Nota],Tabela11[Seleção],G8) -> 66.4375
A9: A | B9: Mexico | C9: Johan Vásquez | D9: 75 | F9: B | G9: Switzerland | H9: =AVERAGEIFS(Tabela11[Nota],Tabela11[Seleção],G9) -> 65.846154
A10: A | B10: Mexico | C10: Richard Ledezma | D10: 73 | F10: C | G10: Brazil | H10: =AVERAGEIFS(Tabela11[Nota],Tabela11[Seleção],G10) -> 71.083333
A11: A | B11: Mexico | C11: Israel Reyes | D11: 75 | F11: C | G11: Morocco | H11: =AVERAGEIFS(Tabela11[Nota],Tabela11[Seleção],G11) -> 74.62069
A12: A | B12: Mexico | C12: Everardo López | D12: 72 | F12: C | G12: Haiti | H12: =AVERAGEIFS(Tabela11[Nota],Tabela11[Seleção],G12) -> 67.36
A13: A | B13: Mexico | C13: Brian Gutiérrez | D13: 68 | F13: C | G13: Scotland | H13: =AVERAGEIFS(Tabela11[Nota],Tabela11[Seleção],G13) -> 73.269231
... A49: A | B49: South Africa | C49: Thapelo Maseko | D49: 70 | F49: L | G49: Panama | H49: =AVERAGEIFS(Tabela11[Nota],Tabela11[Seleção],G49) -> 68.304348
A50: A | B50: South Africa | C50: Relebohile Ratomo | D50: 70
A51: A | B51: South Korea | C51: Kim Seung-Gyu | D51: 72
A52: A | B52: South Korea | C52: Jo Hyeon-Woo | D52: 66
A53: A | B53: South Korea | C53: Song Bum-Keun | D53: 77
A54: A | B54: South Korea | C54: Kim Min-Jae | D54: 59
A55: A | B55: South Korea | C55: Kim Ju-Sung | D55: 58
A56: A | B56: South Korea | C56: Kim Moon-Hwan | D56: 58
A57: A | B57: South Korea | C57: Kim Tae-Hyeon | D57: 50
A58: A | B58: South Korea | C58: Lee Tae-Seok | D58: 69
A59: A | B59: South Korea | C59: Han-Beom Lee | D59: 69
A60: A | B60: South Korea | C60: Seol Young-Woo | D60: 65
A61: A | B61: South Korea | C61: Cho Yu-Min | D61: 69
... A1285: L | B1285: Panama | C1285: José Kadir | D1285: 68

Sheet Jogos (times)
A1: date | B1: match_number | C1: teams | D1: group | E1: stadium | F1: date_dt
A2: 46184 | B2: Match 1 | C2: Mexico v South Africa | D2: Group A | E2: Mexico City Stadium | F2: 46184
A3: 46184 | B3: Match 2 | C3: Korea Republic v Czechia | D3: Group A | E3: Estadio Guadalajara | F3: 46184
A4: 46185 | B4: Match 3 | C4: Canada v Bosnia and Herzegovina | D4: Group B | E4: Toronto Stadium | F4: 46185
A5: 46185 | B5: Match 4 | C5: USA v Paraguay | D5: Group D | E5: Los Angeles Stadium | F5: 46185
A6: 46186 | B6: Match 5 | C6: Haiti v Scotland | D6: Group C | E6: Boston Stadium | F6: 46186
A7: 46186 | B7: Match 6 | C7: Australia v Türkiye | D7: Group D | E7: BC Place Vancouver | F7: 46186
A8: 46186 | B8: Match 7 | C8: Brazil v Morocco | D8: Group C | E8: New York New Jersey Stadium | F8: 46186
A9: 46186 | B9: Match 8 | C9: Qatar v Switzerland | D9: Group B | E9: San Francisco Bay Area Stadium | F9: 46186
A10: 46187 | B10: Match 9 | C10: Côte d'Ivoire v Ecuador | D10: Group E | E10: Philadelphia Stadium | F10: 46187
A11: 46187 | B11: Match 10 | C11: Germany v Curaçao | D11: Group E | E11: Houston Stadium | F11: 46187
A12: 46187 | B12: Match 11 | C12: Netherlands v Japan | D12: Group F | E12: Dallas Stadium | F12: 46187
A13: 46187 | B13: Match 12 | C13: Sweden v Tunisia | D13: Group F | E13: Estadio Monterrey | F13: 46187
... A73: 46200 | B73: Match 72 | C73: Congo DR v Uzbekistan | D73: Group K | E73: Atlanta Stadium | F73: 46200
A74: 46201 | B74: Match 73 | C74: Group A runners-up v Group B runners-up | E74: Los Angeles Stadium | F74: 46201
A75: 46202 | B75: Match 74 | C75: Group E winners v Group A/B/C/D/F third place | E75: Boston Stadium | F75: 46202
A76: 46202 | B76: Match 75 | C76: Group F winners v Group C runners-up | E76: Estadio Monterrey | F76: 46202
A77: 46202 | B77: Match 76 | C77: Group C winners v Group F runners-up | E77: Houston Stadium | F77: 46202
A78: 46203 | B78: Match 77 | C78: Group I winners v Group C/D/F/G/H third place | E78: New York New Jersey Stadium | F78: 46203
A79: 46203 | B79: Match 78 | C79: Group E runners up v Group I runners-up | E79: Dallas Stadium | F79: 46203
A80: 46203 | B80: Match 79 | C80: Group A winners v Group C/E/F/H/I third place | E80: Mexico City Stadium | F80: 46203
A81: 46204 | B81: Match 80 | C81: Group L winners v Group E/H/I/J/K third place | E81: Atlanta Stadium | F81: 46204
A82: 46204 | B82: Match 81 | C82: Group D winners v Group B/E/F/I/J third place | E82: San Francisco Bay Area Stadium | F82: 46204
A83: 46204 | B83: Match 82 | C83: Group G winners v Group A/E/H/I/J third place | E83: Seattle Stadium | F83: 46204
A84: 46205 | B84: Match 83 | C84: Group K runners-up v Group L runners-up | E84: Toronto Stadium | F84: 46205
A85: 46205 | B85: Match 84 | C85: Group H winners v Group J runners-up | E85: Los Angeles Stadium | F85: 46205
... A105: 46222 | B105: Match 104 | C105: Winner match 101 v Winner match 102 | E105: New York New Jersey Stadium | F105: 46222

Sheet Monte Carlo
A1: Time A | B1: =Seleções!B2 -> Mexico | D1: Iteração | E1: Time A | F1: Time B | G1: Gols A (0) | H1: Gols A (1) | I1: Gols A (2) | J1: Gols A (3) | K1: Gols B (0) | L1: Gols B (1) | M1: Gols B (2) | N1: Gols B (3) | Q1: Prob_A | R1: Prob_B | S1: Prob_E | T1: Vencedor | U1: Gols A | V1: Outro | W1: Gols B
A2: x | D2: 1 | E2: =MAX(0,MIN(100,ROUNDDOWN(_xlfn.NORM.INV(RAND(),((_xlfn.XLOOKUP($B$1,teams[Seleção],teams[Média dos jogadores],"",0,1)*'Monte Carlo'!$B$9)+(_xlfn.XLOOKUP($B$1,teams[Seleção],teams[Comissão Técnica],"",0,1)*'Monte Carlo'!$B$10)+(_xlfn.XLOOKUP($B$1,teams[Seleção],teams[FS_Norm],"",0,1)*'Monte Carlo'!$B$11)+(_xlfn.XLOOKUP($B$1,teams[Seleção],teams[ER_norm],"",0,1)*'Monte Carlo'!$B$12)),$B$14),0))) -> 88 | F2: =MAX(0,MIN(100,ROUNDDOWN(_xlfn.NORM.INV(RAND(),((_xlfn.XLOOKUP($B$3,teams[Seleção],teams[Média dos jogadores],"",0,1)*'Monte Carlo'!$B$9)+(_xlfn.XLOOKUP($B$3,teams[Seleção],teams[Comissão Técnica],"",0,1)*'Monte Carlo'!$B$10)+(_xlfn.XLOOKUP($B$3,teams[Seleção],teams[FS_Norm],"",0,1)*'Monte Carlo'!$B$11)+(_xlfn.XLOOKUP($B$3,teams[Seleção],teams[ER_norm],"",0,1)*'Monte Carlo'!$B$12)),$B$14),0))) -> 76 | G2: =_xlfn.POISSON.DIST(0,($B$18*E2/'Monte Carlo'!$B$21),FALSE) -> 0.091110063 | H2: =_xlfn.POISSON.DIST(1,($B$18*E2/'Monte Carlo'!$B$21),0) -> 0.2182712 | I2: =_xlfn.POISSON.DIST(2,($B$18*E2/'Monte Carlo'!$B$21),0) -> 0.26145473 | J2: =_xlfn.POISSON.DIST(3,($B$18*E2/'Monte Carlo'!$B$21),0) -> 0.2087879 | K2: =_xlfn.POISSON.DIST(0,($B$19*F2/'Monte Carlo'!$B$21),0) -> 0.35540361 | L2: =_xlfn.POISSON.DIST(1,($B$19*F2/'Monte Carlo'!$B$21),0) -> 0.36766546 | M2: =_xlfn.POISSON.DIST(2,($B$19*F2/'Monte Carlo'!$B$21),0) -> 0.19017518 | N2: =_xlfn.POISSON.DIST(3,($B$19*F2/'Monte Carlo'!$B$21),0) -> 0.06557882 | Q2: {=SUMPRODUCT(N(E2:E1001>F2:F1001))/1000} -> 0.82 | R2: {=SUMPRODUCT(N(E2:E1001<F2:F1001))/1000} -> 0.158 | S2: {=SUMPRODUCT(N(E2:E1001=F2:F1001))/1000} -> 0.022 | T2: =IF(Q2>R2,$B$1,IF(Q2<R2,$B$3,"Empate")) -> Mexico | U2: =ROUNDDOWN(_xlfn.XLOOKUP(MAX(S12:S27),S12:S27,Q12:Q27,"",0,1),0) & " x " & _xlfn.XLOOKUP(MAX(S12:S27),S12:S27,R12:R27,"",0,1) -> 2 x 0 | V2: =IF(T2=B1,B3) -> South Africa | W2: {=_xlfn.XLOOKUP(MAX(_xlfn._xlws.FILTER(S12:S27,R12:R27>Q12:Q27)),S12:S27,R12:R27,"",0,1) & " x " & _xlfn.XLOOKUP(MAX(_xlfn._xlws.FILTER(S12:S27,R12:R27>Q12:Q27)),S12:S27,Q12:Q27,"",0,1)} -> 1 x 0
A3: Time B | B3: =teams[[#This Row],[Seleção]] -> South Africa | D3: 2 | E3: =MAX(0,MIN(100,ROUNDDOWN(_xlfn.NORM.INV(RAND(),((_xlfn.XLOOKUP($B$1,teams[Seleção],teams[Média dos jogadores],"",0,1)*'Monte Carlo'!$B$9)+(_xlfn.XLOOKUP($B$1,teams[Seleção],teams[Comissão Técnica],"",0,1)*'Monte Carlo'!$B$10)+(_xlfn.XLOOKUP($B$1,teams[Seleção],teams[FS_Norm],"",0,1)*'Monte Carlo'!$B$11)+(_xlfn.XLOOKUP($B$1,teams[Seleção],teams[ER_norm],"",0,1)*'Monte Carlo'!$B$12)),$B$14),0))) -> 95 | F3: =MAX(0,MIN(100,ROUNDDOWN(_xlfn.NORM.INV(RAND(),((_xlfn.XLOOKUP($B$3,teams[Seleção],teams[Média dos jogadores],"",0,1)*'Monte Carlo'!$B$9)+(_xlfn.XLOOKUP($B$3,teams[Seleção],teams[Comissão Técnica],"",0,1)*'Monte Carlo'!$B$10)+(_xlfn.XLOOKUP($B$3,teams[Seleção],teams[FS_Norm],"",0,1)*'Monte Carlo'!$B$11)+(_xlfn.XLOOKUP($B$3,teams[Seleção],teams[ER_norm],"",0,1)*'Monte Carlo'!$B$12)),$B$14),0))) -> 70 | G3: =_xlfn.POISSON.DIST(0,($B$18*E3/'Monte Carlo'!$B$21),FALSE) -> 0.075301665 | H3: =_xlfn.POISSON.DIST(1,($B$18*E3/'Monte Carlo'!$B$21),0) -> 0.19474916 | I3: =_xlfn.POISSON.DIST(2,($B$18*E3/'Monte Carlo'!$B$21),0) -> 0.2518353 | J3: =_xlfn.POISSON.DIST(3,($B$18*E3/'Monte Carlo'!$B$21),0) -> 0.21710327 | K3: =_xlfn.POISSON.DIST(0,($B$19*F3/'Monte Carlo'!$B$21),0) -> 0.38564807 | L3: =_xlfn.POISSON.DIST(1,($B$19*F3/'Monte Carlo'!$B$21),0) -> 0.36745707 | M3: =_xlfn.POISSON.DIST(2,($B$19*F3/'Monte Carlo'!$B$21),0) -> 0.17506207 | N3: =_xlfn.POISSON.DIST(3,($B$19*F3/'Monte Carlo'!$B$21),0) -> 0.055601469
D4: 3 | E4: =MAX(0,MIN(100,ROUNDDOWN(_xlfn.NORM.INV(RAND(),((_xlfn.XLOOKUP($B$1,teams[Seleção],teams[Média dos jogadores],"",0,1)*'Monte Carlo'!$B$9)+(_xlfn.XLOOKUP($B$1,teams[Seleção],teams[Comissão Técnica],"",0,1)*'Monte Carlo'!$B$10)+(_xlfn.XLOOKUP($B$1,teams[Seleção],teams[FS_Norm],"",0,1)*'Monte Carlo'!$B$11)+(_xlfn.XLOOKUP($B$1,teams[Seleção],teams[ER_norm],"",0,1)*'Monte Carlo'!$B$12)),$B$14),0))) -> 72 | F4: =MAX(0,MIN(100,ROUNDDOWN(_xlfn.NORM.INV(RAND(),((_xlfn.XLOOKUP($B$3,teams[Seleção],teams[Média dos jogadores],"",0,1)*'Monte Carlo'!$B$9)+(_xlfn.XLOOKUP($B$3,teams[Seleção],teams[Comissão Técnica],"",0,1)*'Monte Carlo'!$B$10)+(_xlfn.XLOOKUP($B$3,teams[Seleção],teams[FS_Norm],"",0,1)*'Monte Carlo'!$B$11)+(_xlfn.XLOOKUP($B$3,teams[Seleção],teams[ER_norm],"",0,1)*'Monte Carlo'!$B$12)),$B$14),0))) -> 74 | G4: =_xlfn.POISSON.DIST(0,($B$18*E4/'Monte Carlo'!$B$21),FALSE) -> 0.14084327 | H4: =_xlfn.POISSON.DIST(1,($B$18*E4/'Monte Carlo'!$B$21),0) -> 0.27606796 | I4: =_xlfn.POISSON.DIST(2,($B$18*E4/'Monte Carlo'!$B$21),0) -> 0.27056145 | J4: =_xlfn.POISSON.DIST(3,($B$18*E4/'Monte Carlo'!$B$21),0) -> 0.17677651 | K4: =_xlfn.POISSON.DIST(0,($B$19*F4/'Monte Carlo'!$B$21),0) -> 0.36521192 | L4: =_xlfn.POISSON.DIST(1,($B$19*F4/'Monte Carlo'!$B$21),0) -> 0.36786975 | M4: =_xlfn.POISSON.DIST(2,($B$19*F4/'Monte Carlo'!$B$21),0) -> 0.18527346 | N4: =_xlfn.POISSON.DIST(3,($B$19*F4/'Monte Carlo'!$B$21),0) -> 0.062207262
D5: 4 | E5: =MAX(0,MIN(100,ROUNDDOWN(_xlfn.NORM.INV(RAND(),((_xlfn.XLOOKUP($B$1,teams[Seleção],teams[Média dos jogadores],"",0,1)*'Monte Carlo'!$B$9)+(_xlfn.XLOOKUP($B$1,teams[Seleção],teams[Comissão Técnica],"",0,1)*'Monte Carlo'!$B$10)+(_xlfn.XLOOKUP($B$1,teams[Seleção],teams[FS_Norm],"",0,1)*'Monte Carlo'!$B$11)+(_xlfn.XLOOKUP($B$1,teams[Seleção],teams[ER_norm],"",0,1)*'Monte Carlo'!$B$12)),$B$14),0))) -> 57 | F5: =MAX(0,MIN(100,ROUNDDOWN(_xlfn.NORM.INV(RAND(),((_xlfn.XLOOKUP($B$3,teams[Seleção],teams[Média dos jogadores],"",0,1)*'Monte Carlo'!$B$9)+(_xlfn.XLOOKUP($B$3,teams[Seleção],teams[Comissão Técnica],"",0,1)*'Monte Carlo'!$B$10)+(_xlfn.XLOOKUP($B$3,teams[Seleção],teams[FS_Norm],"",0,1)*'Monte Carlo'!$B$11)+(_xlfn.XLOOKUP($B$3,teams[Seleção],teams[ER_norm],"",0,1)*'Monte Carlo'!$B$12)),$B$14),0))) -> 64 | G5: =_xlfn.POISSON.DIST(0,($B$18*E5/'Monte Carlo'!$B$21),FALSE) -> 0.21187648 | H5: =_xlfn.POISSON.DIST(1,($B$18*E5/'Monte Carlo'!$B$21),0) -> 0.32877971 | I5: =_xlfn.POISSON.DIST(2,($B$18*E5/'Monte Carlo'!$B$21),0) -> 0.25509226 | J5: =_xlfn.POISSON.DIST(3,($B$18*E5/'Monte Carlo'!$B$21),0) -> 0.13194663 | K5: =_xlfn.POISSON.DIST(0,($B$19*F5/'Monte Carlo'!$B$21),0) -> 0.4184663 | L5: =_xlfn.POISSON.DIST(1,($B$19*F5/'Monte Carlo'!$B$21),0) -> 0.36455065 | M5: =_xlfn.POISSON.DIST(2,($B$19*F5/'Monte Carlo'!$B$21),0) -> 0.15879077 | N5: =_xlfn.POISSON.DIST(3,($B$19*F5/'Monte Carlo'!$B$21),0) -> 0.046110666
D6: 5 | E6: =MAX(0,MIN(100,ROUNDDOWN(_xlfn.NORM.INV(RAND(),((_xlfn.XLOOKUP($B$1,teams[Seleção],teams[Média dos jogadores],"",0,1)*'Monte Carlo'!$B$9)+(_xlfn.XLOOKUP($B$1,teams[Seleção],teams[Comissão Técnica],"",0,1)*'Monte Carlo'!$B$10)+(_xlfn.XLOOKUP($B$1,teams[Seleção],teams[FS_Norm],"",0,1)*'Monte Carlo'!$B$11)+(_xlfn.XLOOKUP($B$1,teams[Seleção],teams[ER_norm],"",0,1)*'Monte Carlo'!$B$12)),$B$14),0))) -> 69 | F6: =MAX(0,MIN(100,ROUNDDOWN(_xlfn.NORM.INV(RAND(),((_xlfn.XLOOKUP($B$3,teams[Seleção],teams[Média dos jogadores],"",0,1)*'Monte Carlo'!$B$9)+(_xlfn.XLOOKUP($B$3,teams[Seleção],teams[Comissão Técnica],"",0,1)*'Monte Carlo'!$B$10)+(_xlfn.XLOOKUP($B$3,teams[Seleção],teams[FS_Norm],"",0,1)*'Monte Carlo'!$B$11)+(_xlfn.XLOOKUP($B$3,teams[Seleção],teams[ER_norm],"",0,1)*'Monte Carlo'!$B$12)),$B$14),0))) -> 66 | G6: =_xlfn.POISSON.DIST(0,($B$18*E6/'Monte Carlo'!$B$21),FALSE) -> 0.15282888 | H6: =_xlfn.POISSON.DIST(1,($B$18*E6/'Monte Carlo'!$B$21),0) -> 0.28707933 | I6: =_xlfn.POISSON.DIST(2,($B$18*E6/'Monte Carlo'!$B$21),0) -> 0.26963014 | J6: =_xlfn.POISSON.DIST(3,($B$18*E6/'Monte Carlo'!$B$21),0) -> 0.16882769 | K6: =_xlfn.POISSON.DIST(0,($B$19*F6/'Monte Carlo'!$B$21),0) -> 0.40722776 | L6: =_xlfn.POISSON.DIST(1,($B$19*F6/'Monte Carlo'!$B$21),0) -> 0.36584635 | M6: =_xlfn.POISSON.DIST(2,($B$19*F6/'Monte Carlo'!$B$21),0) -> 0.164335 | N6: =_xlfn.POISSON.DIST(3,($B$19*F6/'Monte Carlo'!$B$21),0) -> 0.049211905
D7: 6 | E7: =MAX(0,MIN(100,ROUNDDOWN(_xlfn.NORM.INV(RAND(),((_xlfn.XLOOKUP($B$1,teams[Seleção],teams[Média dos jogadores],"",0,1)*'Monte Carlo'!$B$9)+(_xlfn.XLOOKUP($B$1,teams[Seleção],teams[Comissão Técnica],"",0,1)*'Monte Carlo'!$B$10)+(_xlfn.XLOOKUP($B$1,teams[Seleção],teams[FS_Norm],"",0,1)*'Monte Carlo'!$B$11)+(_xlfn.XLOOKUP($B$1,teams[Seleção],teams[ER_norm],"",0,1)*'Monte Carlo'!$B$12)),$B$14),0))) -> 79 | F7: =MAX(0,MIN(100,ROUNDDOWN(_xlfn.NORM.INV(RAND(),((_xlfn.XLOOKUP($B$3,teams[Seleção],teams[Média dos jogadores],"",0,1)*'Monte Carlo'!$B$9)+(_xlfn.XLOOKUP($B$3,teams[Seleção],teams[Comissão Técnica],"",0,1)*'Monte Carlo'!$B$10)+(_xlfn.XLOOKUP($B$3,teams[Seleção],teams[FS_Norm],"",0,1)*'Monte Carlo'!$B$11)+(_xlfn.XLOOKUP($B$3,teams[Seleção],teams[ER_norm],"",0,1)*'Monte Carlo'!$B$12)),$B$14),0))) -> 53 | G7: =_xlfn.POISSON.DIST(0,($B$18*E7/'Monte Carlo'!$B$21),FALSE) -> 0.11640572 | H7: =_xlfn.POISSON.DIST(1,($B$18*E7/'Monte Carlo'!$B$21),0) -> 0.25035071 | I7: =_xlfn.POISSON.DIST(2,($B$18*E7/'Monte Carlo'!$B$21),0) -> 0.26921133 | J7: =_xlfn.POISSON.DIST(3,($B$18*E7/'Monte Carlo'!$B$21),0) -> 0.19299523 | K7: =_xlfn.POISSON.DIST(0,($B$19*F7/'Monte Carlo'!$B$21),0) -> 0.48605744 | L7: =_xlfn.POISSON.DIST(1,($B$19*F7/'Monte Carlo'!$B$21),0) -> 0.35065568 | M7: =_xlfn.POISSON.DIST(2,($B$19*F7/'Monte Carlo'!$B$21),0) -> 0.1264865 | N7: =_xlfn.POISSON.DIST(3,($B$19*F7/'Monte Carlo'!$B$21),0) -> 0.030416987
A8: Peso | B8: Peso_Norm | D8: 7 | E8: =MAX(0,MIN(100,ROUNDDOWN(_xlfn.NORM.INV(RAND(),((_xlfn.XLOOKUP($B$1,teams[Seleção],teams[Média dos jogadores],"",0,1)*'Monte Carlo'!$B$9)+(_xlfn.XLOOKUP($B$1,teams[Seleção],teams[Comissão Técnica],"",0,1)*'Monte Carlo'!$B$10)+(_xlfn.XLOOKUP($B$1,teams[Seleção],teams[FS_Norm],"",0,1)*'Monte Carlo'!$B$11)+(_xlfn.XLOOKUP($B$1,teams[Seleção],teams[ER_norm],"",0,1)*'Monte Carlo'!$B$12)),$B$14),0))) -> 78 | F8: =MAX(0,MIN(100,ROUNDDOWN(_xlfn.NORM.INV(RAND(),((_xlfn.XLOOKUP($B$3,teams[Seleção],teams[Média dos jogadores],"",0,1)*'Monte Carlo'!$B$9)+(_xlfn.XLOOKUP($B$3,teams[Seleção],teams[Comissão Técnica],"",0,1)*'Monte Carlo'!$B$10)+(_xlfn.XLOOKUP($B$3,teams[Seleção],teams[FS_Norm],"",0,1)*'Monte Carlo'!$B$11)+(_xlfn.XLOOKUP($B$3,teams[Seleção],teams[ER_norm],"",0,1)*'Monte Carlo'!$B$12)),$B$14),0))) -> 56 | G8: =_xlfn.POISSON.DIST(0,($B$18*E8/'Monte Carlo'!$B$21),FALSE) -> 0.11961825 | H8: =_xlfn.POISSON.DIST(1,($B$18*E8/'Monte Carlo'!$B$21),0) -> 0.25400336 | I8: =_xlfn.POISSON.DIST(2,($B$18*E8/'Monte Carlo'!$B$21),0) -> 0.26968169 | J8: =_xlfn.POISSON.DIST(3,($B$18*E8/'Monte Carlo'!$B$21),0) -> 0.19088519 | K8: =_xlfn.POISSON.DIST(0,($B$19*F8/'Monte Carlo'!$B$21),0) -> 0.4666088 | L8: =_xlfn.POISSON.DIST(1,($B$19*F8/'Monte Carlo'!$B$21),0) -> 0.35567912 | M8: =_xlfn.POISSON.DIST(2,($B$19*F8/'Monte Carlo'!$B$21),0) -> 0.1355607 | N8: =_xlfn.POISSON.DIST(3,($B$19*F8/'Monte Carlo'!$B$21),0) -> 0.03444435
A9: =RANDBETWEEN(10,40) -> 19 | B9: =A9/SUM($A$9:$A$12) -> 0.22093023 | D9: 8 | E9: =MAX(0,MIN(100,ROUNDDOWN(_xlfn.NORM.INV(RAND(),((_xlfn.XLOOKUP($B$1,teams[Seleção],teams[Média dos jogadores],"",0,1)*'Monte Carlo'!$B$9)+(_xlfn.XLOOKUP($B$1,teams[Seleção],teams[Comissão Técnica],"",0,1)*'Monte Carlo'!$B$10)+(_xlfn.XLOOKUP($B$1,teams[Seleção],teams[FS_Norm],"",0,1)*'Monte Carlo'!$B$11)+(_xlfn.XLOOKUP($B$1,teams[Seleção],teams[ER_norm],"",0,1)*'Monte Carlo'!$B$12)),$B$14),0))) -> 76 | F9: =MAX(0,MIN(100,ROUNDDOWN(_xlfn.NORM.INV(RAND(),((_xlfn.XLOOKUP($B$3,teams[Seleção],teams[Média dos jogadores],"",0,1)*'Monte Carlo'!$B$9)+(_xlfn.XLOOKUP($B$3,teams[Seleção],teams[Comissão Técnica],"",0,1)*'Monte Carlo'!$B$10)+(_xlfn.XLOOKUP($B$3,teams[Seleção],teams[FS_Norm],"",0,1)*'Monte Carlo'!$B$11)+(_xlfn.XLOOKUP($B$3,teams[Seleção],teams[ER_norm],"",0,1)*'Monte Carlo'!$B$12)),$B$14),0))) -> 48 | G9: =_xlfn.POISSON.DIST(0,($B$18*E9/'Monte Carlo'!$B$21),FALSE) -> 0.12631172 | H9: =_xlfn.POISSON.DIST(1,($B$18*E9/'Monte Carlo'!$B$21),0) -> 0.26133926 | I9: =_xlfn.POISSON.DIST(2,($B$18*E9/'Monte Carlo'!$B$21),0) -> 0.27035579 | J9: =_xlfn.POISSON.DIST(3,($B$18*E9/'Monte Carlo'!$B$21),0) -> 0.18645559 | K9: =_xlfn.POISSON.DIST(0,($B$19*F9/'Monte Carlo'!$B$21),0) -> 0.52028987 | L9: =_xlfn.POISSON.DIST(1,($B$19*F9/'Monte Carlo'!$B$21),0) -> 0.33994137 | M9: =_xlfn.POISSON.DIST(2,($B$19*F9/'Monte Carlo'!$B$21),0) -> 0.11105361 | N9: =_xlfn.POISSON.DIST(3,($B$19*F9/'Monte Carlo'!$B$21),0) -> 0.024186335
A10: =RANDBETWEEN(10,20) -> 14 | B10: =A10/SUM($A$9:$A$12) -> 0.1627907 | D10: 9 | E10: =MAX(0,MIN(100,ROUNDDOWN(_xlfn.NORM.INV(RAND(),((_xlfn.XLOOKUP($B$1,teams[Seleção],teams[Média dos jogadores],"",0,1)*'Monte Carlo'!$B$9)+(_xlfn.XLOOKUP($B$1,teams[Seleção],teams[Comissão Técnica],"",0,1)*'Monte Carlo'!$B$10)+(_xlfn.XLOOKUP($B$1,teams[Seleção],teams[FS_Norm],"",0,1)*'Monte Carlo'!$B$11)+(_xlfn.XLOOKUP($B$1,teams[Seleção],teams[ER_norm],"",0,1)*'Monte Carlo'!$B$12)),$B$14),0))) -> 82 | F10: =MAX(0,MIN(100,ROUNDDOWN(_xlfn.NORM.INV(RAND(),((_xlfn.XLOOKUP($B$3,teams[Seleção],teams[Média dos jogadores],"",0,1)*'Monte Carlo'!$B$9)+(_xlfn.XLOOKUP($B$3,teams[Seleção],teams[Comissão Técnica],"",0,1)*'Monte Carlo'!$B$10)+(_xlfn.XLOOKUP($B$3,teams[Seleção],teams[FS_Norm],"",0,1)*'Monte Carlo'!$B$11)+(_xlfn.XLOOKUP($B$3,teams[Seleção],teams[ER_norm],"",0,1)*'Monte Carlo'!$B$12)),$B$14),0))) -> 74 | G10: =_xlfn.POISSON.DIST(0,($B$18*E10/'Monte Carlo'!$B$21),FALSE) -> 0.1072766 | H10: =_xlfn.POISSON.DIST(1,($B$18*E10/'Monte Carlo'!$B$21),0) -> 0.23947835 | I10: =_xlfn.POISSON.DIST(2,($B$18*E10/'Monte Carlo'!$B$21),0) -> 0.26729912 | J10: =_xlfn.POISSON.DIST(3,($B$18*E10/'Monte Carlo'!$B$21),0) -> 0.19890126 | K10: =_xlfn.POISSON.DIST(0,($B$19*F10/'Monte Carlo'!$B$21),0) -> 0.36521192 | L10: =_xlfn.POISSON.DIST(1,($B$19*F10/'Monte Carlo'!$B$21),0) -> 0.36786975 | M10: =_xlfn.POISSON.DIST(2,($B$19*F10/'Monte Carlo'!$B$21),0) -> 0.18527346 | N10: =_xlfn.POISSON.DIST(3,($B$19*F10/'Monte Carlo'!$B$21),0) -> 0.062207262
A11: =RANDBETWEEN(10,20) -> 16 | B11: =A11/SUM($A$9:$A$12) -> 0.18604651 | D11: 10 | E11: =MAX(0,MIN(100,ROUNDDOWN(_xlfn.NORM.INV(RAND(),((_xlfn.XLOOKUP($B$1,teams[Seleção],teams[Média dos jogadores],"",0,1)*'Monte Carlo'!$B$9)+(_xlfn.XLOOKUP($B$1,teams[Seleção],teams[Comissão Técnica],"",0,1)*'Monte Carlo'!$B$10)+(_xlfn.XLOOKUP($B$1,teams[Seleção],teams[FS_Norm],"",0,1)*'Monte Carlo'!$B$11)+(_xlfn.XLOOKUP($B$1,teams[Seleção],teams[ER_norm],"",0,1)*'Monte Carlo'!$B$12)),$B$14),0))) -> 80 | F11: =MAX(0,MIN(100,ROUNDDOWN(_xlfn.NORM.INV(RAND(),((_xlfn.XLOOKUP($B$3,teams[Seleção],teams[Média dos jogadores],"",0,1)*'Monte Carlo'!$B$9)+(_xlfn.XLOOKUP($B$3,teams[Seleção],teams[Comissão Técnica],"",0,1)*'Monte Carlo'!$B$10)+(_xlfn.XLOOKUP($B$3,teams[Seleção],teams[FS_Norm],"",0,1)*'Monte Carlo'!$B$11)+(_xlfn.XLOOKUP($B$3,teams[Seleção],teams[ER_norm],"",0,1)*'Monte Carlo'!$B$12)),$B$14),0))) -> 45 | G11: =_xlfn.POISSON.DIST(0,($B$18*E11/'Monte Carlo'!$B$21),FALSE) -> 0.11327947 | H11: =_xlfn.POISSON.DIST(1,($B$18*E11/'Monte Carlo'!$B$21),0) -> 0.24671106 | I11: =_xlfn.POISSON.DIST(2,($B$18*E11/'Monte Carlo'!$B$21),0) -> 0.26865567 | J11: =_xlfn.POISSON.DIST(3,($B$18*E11/'Monte Carlo'!$B$21),0) -> 0.19503482 | K11: =_xlfn.POISSON.DIST(0,($B$19*F11/'Monte Carlo'!$B$21),0) -> 0.54197597 | L11: =_xlfn.POISSON.DIST(1,($B$19*F11/'Monte Carlo'!$B$21),0) -> 0.3319785 | M11: =_xlfn.POISSON.DIST(2,($B$19*F11/'Monte Carlo'!$B$21),0) -> 0.10167399 | N11: =_xlfn.POISSON.DIST(3,($B$19*F11/'Monte Carlo'!$B$21),0) -> 0.02075958 | Q11: A | R11: B | S11: Prob
A12: =RANDBETWEEN(10,40) -> 37 | B12: =A12/SUM($A$9:$A$12) -> 0.43023256 | D12: 11 | E12: =MAX(0,MIN(100,ROUNDDOWN(_xlfn.NORM.INV(RAND(),((_xlfn.XLOOKUP($B$1,teams[Seleção],teams[Média dos jogadores],"",0,1)*'Monte Carlo'!$B$9)+(_xlfn.XLOOKUP($B$1,teams[Seleção],teams[Comissão Técnica],"",0,1)*'Monte Carlo'!$B$10)+(_xlfn.XLOOKUP($B$1,teams[Seleção],teams[FS_Norm],"",0,1)*'Monte Carlo'!$B$11)+(_xlfn.XLOOKUP($B$1,teams[Seleção],teams[ER_norm],"",0,1)*'Monte Carlo'!$B$12)),$B$14),0))) -> 78 | F12: =MAX(0,MIN(100,ROUNDDOWN(_xlfn.NORM.INV(RAND(),((_xlfn.XLOOKUP($B$3,teams[Seleção],teams[Média dos jogadores],"",0,1)*'Monte Carlo'!$B$9)+(_xlfn.XLOOKUP($B$3,teams[Seleção],teams[Comissão Técnica],"",0,1)*'Monte Carlo'!$B$10)+(_xlfn.XLOOKUP($B$3,teams[Seleção],teams[FS_Norm],"",0,1)*'Monte Carlo'!$B$11)+(_xlfn.XLOOKUP($B$3,teams[Seleção],teams[ER_norm],"",0,1)*'Monte Carlo'!$B$12)),$B$14),0))) -> 72 | G12: =_xlfn.POISSON.DIST(0,($B$18*E12/'Monte Carlo'!$B$21),FALSE) -> 0.11961825 | H12: =_xlfn.POISSON.DIST(1,($B$18*E12/'Monte Carlo'!$B$21),0) -> 0.25400336 | I12: =_xlfn.POISSON.DIST(2,($B$18*E12/'Monte Carlo'!$B$21),0) -> 0.26968169 | J12: =_xlfn.POISSON.DIST(3,($B$18*E12/'Monte Carlo'!$B$21),0) -> 0.19088519 | K12: =_xlfn.POISSON.DIST(0,($B$19*F12/'Monte Carlo'!$B$21),0) -> 0.37529091 | L12: =_xlfn.POISSON.DIST(1,($B$19*F12/'Monte Carlo'!$B$21),0) -> 0.36780528 | M12: =_xlfn.POISSON.DIST(2,($B$19*F12/'Monte Carlo'!$B$21),0) -> 0.18023448 | N12: =_xlfn.POISSON.DIST(3,($B$19*F12/'Monte Carlo'!$B$21),0) -> 0.058879827 | Q12: 0 | R12: 0 | S12: =AVERAGE($G$2:$G$1001)*AVERAGE($K$2:$K$1001) -> 0.049546996
D13: 12 | E13: =MAX(0,MIN(100,ROUNDDOWN(_xlfn.NORM.INV(RAND(),((_xlfn.XLOOKUP($B$1,teams[Seleção],teams[Média dos jogadores],"",0,1)*'Monte Carlo'!$B$9)+(_xlfn.XLOOKUP($B$1,teams[Seleção],teams[Comissão Técnica],"",0,1)*'Monte Carlo'!$B$10)+(_xlfn.XLOOKUP($B$1,teams[Seleção],teams[FS_Norm],"",0,1)*'Monte Carlo'!$B$11)+(_xlfn.XLOOKUP($B$1,teams[Seleção],teams[ER_norm],"",0,1)*'Monte Carlo'!$B$12)),$B$14),0))) -> 84 | F13: =MAX(0,MIN(100,ROUNDDOWN(_xlfn.NORM.INV(RAND(),((_xlfn.XLOOKUP($B$3,teams[Seleção],teams[Média dos jogadores],"",0,1)*'Monte Carlo'!$B$9)+(_xlfn.XLOOKUP($B$3,teams[Seleção],teams[Comissão Técnica],"",0,1)*'Monte Carlo'!$B$10)+(_xlfn.XLOOKUP($B$3,teams[Seleção],teams[FS_Norm],"",0,1)*'Monte Carlo'!$B$11)+(_xlfn.XLOOKUP($B$3,teams[Seleção],teams[ER_norm],"",0,1)*'Monte Carlo'!$B$12)),$B$14),0))) -> 66 | G13: =_xlfn.POISSON.DIST(0,($B$18*E13/'Monte Carlo'!$B$21),FALSE) -> 0.10159183 | H13: =_xlfn.POISSON.DIST(1,($B$18*E13/'Monte Carlo'!$B$21),0) -> 0.2323194 | I13: =_xlfn.POISSON.DIST(2,($B$18*E13/'Monte Carlo'!$B$21),0) -> 0.26563309 | J13: =_xlfn.POISSON.DIST(3,($B$18*E13/'Monte Carlo'!$B$21),0) -> 0.20248256 | K13: =_xlfn.POISSON.DIST(0,($B$19*F13/'Monte Carlo'!$B$21),0) -> 0.40722776 | L13: =_xlfn.POISSON.DIST(1,($B$19*F13/'Monte Carlo'!$B$21),0) -> 0.36584635 | M13: =_xlfn.POISSON.DIST(2,($B$19*F13/'Monte Carlo'!$B$21),0) -> 0.164335 | N13: =_xlfn.POISSON.DIST(3,($B$19*F13/'Monte Carlo'!$B$21),0) -> 0.049211905 | Q13: 0 | R13: 1 | S13: =AVERAGE($G$2:$G$1001)*AVERAGE($L$2:$L$1001) -> 0.043362408
A14: Zebra | B14: 10 | D14: 13 | E14: =MAX(0,MIN(100,ROUNDDOWN(_xlfn.NORM.INV(RAND(),((_xlfn.XLOOKUP($B$1,teams[Seleção],teams[Média dos jogadores],"",0,1)*'Monte Carlo'!$B$9)+(_xlfn.XLOOKUP($B$1,teams[Seleção],teams[Comissão Técnica],"",0,1)*'Monte Carlo'!$B$10)+(_xlfn.XLOOKUP($B$1,teams[Seleção],teams[FS_Norm],"",0,1)*'Monte Carlo'!$B$11)+(_xlfn.XLOOKUP($B$1,teams[Seleção],teams[ER_norm],"",0,1)*'Monte Carlo'!$B$12)),$B$14),0))) -> 79 | F14: =MAX(0,MIN(100,ROUNDDOWN(_xlfn.NORM.INV(RAND(),((_xlfn.XLOOKUP($B$3,teams[Seleção],teams[Média dos jogadores],"",0,1)*'Monte Carlo'!$B$9)+(_xlfn.XLOOKUP($B$3,teams[Seleção],teams[Comissão Técnica],"",0,1)*'Monte Carlo'!$B$10)+(_xlfn.XLOOKUP($B$3,teams[Seleção],teams[FS_Norm],"",0,1)*'Monte Carlo'!$B$11)+(_xlfn.XLOOKUP($B$3,teams[Seleção],teams[ER_norm],"",0,1)*'Monte Carlo'!$B$12)),$B$14),0))) -> 62 | G14: =_xlfn.POISSON.DIST(0,($B$18*E14/'Monte Carlo'!$B$21),FALSE) -> 0.11640572 | H14: =_xlfn.POISSON.DIST(1,($B$18*E14/'Monte Carlo'!$B$21),0) -> 0.25035071 | I14: =_xlfn.POISSON.DIST(2,($B$18*E14/'Monte Carlo'!$B$21),0) -> 0.26921133 | J14: =_xlfn.POISSON.DIST(3,($B$18*E14/'Monte Carlo'!$B$21),0) -> 0.19299523 | K14: =_xlfn.POISSON.DIST(0,($B$19*F14/'Monte Carlo'!$B$21),0) -> 0.43001499 | L14: =_xlfn.POISSON.DIST(1,($B$19*F14/'Monte Carlo'!$B$21),0) -> 0.36290479 | M14: =_xlfn.POISSON.DIST(2,($B$19*F14/'Monte Carlo'!$B$21),0) -> 0.15313406 | N14: =_xlfn.POISSON.DIST(3,($B$19*F14/'Monte Carlo'!$B$21),0) -> 0.043078409 | Q14: 0 | R14: 2 | S14: =AVERAGE($G$2:$G$1001)*AVERAGE($M$2:$M$1001) -> 0.019477619
D15: 14 | E15: =MAX(0,MIN(100,ROUNDDOWN(_xlfn.NORM.INV(RAND(),((_xlfn.XLOOKUP($B$1,teams[Seleção],teams[Média dos jogadores],"",0,1)*'Monte Carlo'!$B$9)+(_xlfn.XLOOKUP($B$1,teams[Seleção],teams[Comissão Técnica],"",0,1)*'Monte Carlo'!$B$10)+(_xlfn.XLOOKUP($B$1,teams[Seleção],teams[FS_Norm],"",0,1)*'Monte Carlo'!$B$11)+(_xlfn.XLOOKUP($B$1,teams[Seleção],teams[ER_norm],"",0,1)*'Monte Carlo'!$B$12)),$B$14),0))) -> 85 | F15: =MAX(0,MIN(100,ROUNDDOWN(_xlfn.NORM.INV(RAND(),((_xlfn.XLOOKUP($B$3,teams[Seleção],teams[Média dos jogadores],"",0,1)*'Monte Carlo'!$B$9)+(_xlfn.XLOOKUP($B$3,teams[Seleção],teams[Comissão Técnica],"",0,1)*'Monte Carlo'!$B$10)+(_xlfn.XLOOKUP($B$3,teams[Seleção],teams[FS_Norm],"",0,1)*'Monte Carlo'!$B$11)+(_xlfn.XLOOKUP($B$3,teams[Seleção],teams[ER_norm],"",0,1)*'Monte Carlo'!$B$12)),$B$14),0))) -> 62 | G15: =_xlfn.POISSON.DIST(0,($B$18*E15/'Monte Carlo'!$B$21),FALSE) -> 0.09886343 | H15: =_xlfn.POISSON.DIST(1,($B$18*E15/'Monte Carlo'!$B$21),0) -> 0.22877155 | I15: =_xlfn.POISSON.DIST(2,($B$18*E15/'Monte Carlo'!$B$21),0) -> 0.2646905 | J15: =_xlfn.POISSON.DIST(3,($B$18*E15/'Monte Carlo'!$B$21),0) -> 0.204166 | K15: =_xlfn.POISSON.DIST(0,($B$19*F15/'Monte Carlo'!$B$21),0) -> 0.43001499 | L15: =_xlfn.POISSON.DIST(1,($B$19*F15/'Monte Carlo'!$B$21),0) -> 0.36290479 | M15: =_xlfn.POISSON.DIST(2,($B$19*F15/'Monte Carlo'!$B$21),0) -> 0.15313406 | N15: =_xlfn.POISSON.DIST(3,($B$19*F15/'Monte Carlo'!$B$21),0) -> 0.043078409 | Q15: 0 | R15: 3 | S15: =AVERAGE($G$2:$G$1001)*AVERAGE($N$2:$N$1001) -> 0.0059772877
D16: 15 | E16: =MAX(0,MIN(100,ROUNDDOWN(_xlfn.NORM.INV(RAND(),((_xlfn.XLOOKUP($B$1,teams[Seleção],teams[Média dos jogadores],"",0,1)*'Monte Carlo'!$B$9)+(_xlfn.XLOOKUP($B$1,teams[Seleção],teams[Comissão Técnica],"",0,1)*'Monte Carlo'!$B$10)+(_xlfn.XLOOKUP($B$1,teams[Seleção],teams[FS_Norm],"",0,1)*'Monte Carlo'!$B$11)+(_xlfn.XLOOKUP($B$1,teams[Seleção],teams[ER_norm],"",0,1)*'Monte Carlo'!$B$12)),$B$14),0))) -> 90 | F16: =MAX(0,MIN(100,ROUNDDOWN(_xlfn.NORM.INV(RAND(),((_xlfn.XLOOKUP($B$3,teams[Seleção],teams[Média dos jogadores],"",0,1)*'Monte Carlo'!$B$9)+(_xlfn.XLOOKUP($B$3,teams[Seleção],teams[Comissão Técnica],"",0,1)*'Monte Carlo'!$B$10)+(_xlfn.XLOOKUP($B$3,teams[Seleção],teams[FS_Norm],"",0,1)*'Monte Carlo'!$B$11)+(_xlfn.XLOOKUP($B$3,teams[Seleção],teams[ER_norm],"",0,1)*'Monte Carlo'!$B$12)),$B$14),0))) -> 92 | G16: =_xlfn.POISSON.DIST(0,($B$18*E16/'Monte Carlo'!$B$21),FALSE) -> 0.086281985 | H16: =_xlfn.POISSON.DIST(1,($B$18*E16/'Monte Carlo'!$B$21),0) -> 0.21140246 | I16: =_xlfn.POISSON.DIST(2,($B$18*E16/'Monte Carlo'!$B$21),0) -> 0.25898223 | J16: =_xlfn.POISSON.DIST(3,($B$18*E16/'Monte Carlo'!$B$21),0) -> 0.21151376 | K16: =_xlfn.POISSON.DIST(0,($B$19*F16/'Monte Carlo'!$B$21),0) -> 0.28584918 | L16: =_xlfn.POISSON.DIST(1,($B$19*F16/'Monte Carlo'!$B$21),0) -> 0.35796634 | M16: =_xlfn.POISSON.DIST(2,($B$19*F16/'Monte Carlo'!$B$21),0) -> 0.224139 | N16: =_xlfn.POISSON.DIST(3,($B$19*F16/'Monte Carlo'!$B$21),0) -> 0.093562415 | Q16: 1 | R16: 0 | S16: =AVERAGE($H$2:$H$1001)*AVERAGE($K$2:$K$1001) -> 0.10317936
A17: Poisson (gols) | D17: 16 | E17: =MAX(0,MIN(100,ROUNDDOWN(_xlfn.NORM.INV(RAND(),((_xlfn.XLOOKUP($B$1,teams[Seleção],teams[Média dos jogadores],"",0,1)*'Monte Carlo'!$B$9)+(_xlfn.XLOOKUP($B$1,teams[Seleção],teams[Comissão Técnica],"",0,1)*'Monte Carlo'!$B$10)+(_xlfn.XLOOKUP($B$1,teams[Seleção],teams[FS_Norm],"",0,1)*'Monte Carlo'!$B$11)+(_xlfn.XLOOKUP($B$1,teams[Seleção],teams[ER_norm],"",0,1)*'Monte Carlo'!$B$12)),$B$14),0))) -> 73 | F17: =MAX(0,MIN(100,ROUNDDOWN(_xlfn.NORM.INV(RAND(),((_xlfn.XLOOKUP($B$3,teams[Seleção],teams[Média dos jogadores],"",0,1)*'Monte Carlo'!$B$9)+(_xlfn.XLOOKUP($B$3,teams[Seleção],teams[Comissão Técnica],"",0,1)*'Monte Carlo'!$B$10)+(_xlfn.XLOOKUP($B$3,teams[Seleção],teams[FS_Norm],"",0,1)*'Monte Carlo'!$B$11)+(_xlfn.XLOOKUP($B$3,teams[Seleção],teams[ER_norm],"",0,1)*'Monte Carlo'!$B$12)),$B$14),0))) -> 36 | G17: =_xlfn.POISSON.DIST(0,($B$18*E17/'Monte Carlo'!$B$21),FALSE) -> 0.13706071 | H17: =_xlfn.POISSON.DIST(1,($B$18*E17/'Monte Carlo'!$B$21),0) -> 0.27238505 | I17: =_xlfn.POISSON.DIST(2,($B$18*E17/'Monte Carlo'!$B$21),0) -> 0.27065966 | J17: =_xlfn.POISSON.DIST(3,($B$18*E17/'Monte Carlo'!$B$21),0) -> 0.1792968 | K17: =_xlfn.POISSON.DIST(0,($B$19*F17/'Monte Carlo'!$B$21),0) -> 0.61260992 | L17: =_xlfn.POISSON.DIST(1,($B$19*F17/'Monte Carlo'!$B$21),0) -> 0.30019533 | M17: =_xlfn.POISSON.DIST(2,($B$19*F17/'Monte Carlo'!$B$21),0) -> 0.073551893 | N17: =_xlfn.POISSON.DIST(3,($B$19*F17/'Monte Carlo'!$B$21),0) -> 0.012014135 | Q17: 1 | R17: 1 | S17: =AVERAGE($H$2:$H$1001)*AVERAGE($L$2:$L$1001) -> 0.090300238
A18: λA | B18: =ROUND((_xlfn.XLOOKUP($B$1,Tabela8[Seleção],Tabela8[Média de gols feitos],"",0,1)+_xlfn.XLOOKUP('Monte Carlo'!$B$3,Tabela8[Seleção],Tabela8[Média de gols sofridos],"",0,1))/2,0) -> 2 | D18: 17 | E18: =MAX(0,MIN(100,ROUNDDOWN(_xlfn.NORM.INV(RAND(),((_xlfn.XLOOKUP($B$1,teams[Seleção],teams[Média dos jogadores],"",0,1)*'Monte Carlo'!$B$9)+(_xlfn.XLOOKUP($B$1,teams[Seleção],teams[Comissão Técnica],"",0,1)*'Monte Carlo'!$B$10)+(_xlfn.XLOOKUP($B$1,teams[Seleção],teams[FS_Norm],"",0,1)*'Monte Carlo'!$B$11)+(_xlfn.XLOOKUP($B$1,teams[Seleção],teams[ER_norm],"",0,1)*'Monte Carlo'!$B$12)),$B$14),0))) -> 85 | F18: =MAX(0,MIN(100,ROUNDDOWN(_xlfn.NORM.INV(RAND(),((_xlfn.XLOOKUP($B$3,teams[Seleção],teams[Média dos jogadores],"",0,1)*'Monte Carlo'!$B$9)+(_xlfn.XLOOKUP($B$3,teams[Seleção],teams[Comissão Técnica],"",0,1)*'Monte Carlo'!$B$10)+(_xlfn.XLOOKUP($B$3,teams[Seleção],teams[FS_Norm],"",0,1)*'Monte Carlo'!$B$11)+(_xlfn.XLOOKUP($B$3,teams[Seleção],teams[ER_norm],"",0,1)*'Monte Carlo'!$B$12)),$B$14),0))) -> 68 | G18: =_xlfn.POISSON.DIST(0,($B$18*E18/'Monte Carlo'!$B$21),FALSE) -> 0.09886343 | H18: =_xlfn.POISSON.DIST(1,($B$18*E18/'Monte Carlo'!$B$21),0) -> 0.22877155 | I18: =_xlfn.POISSON.DIST(2,($B$18*E18/'Monte Carlo'!$B$21),0) -> 0.2646905 | J18: =_xlfn.POISSON.DIST(3,($B$18*E18/'Monte Carlo'!$B$21),0) -> 0.204166 | K18: =_xlfn.POISSON.DIST(0,($B$19*F18/'Monte Carlo'!$B$21),0) -> 0.39629106 | L18: =_xlfn.POISSON.DIST(1,($B$19*F18/'Monte Carlo'!$B$21),0) -> 0.36680952 | M18: =_xlfn.POISSON.DIST(2,($B$19*F18/'Monte Carlo'!$B$21),0) -> 0.16976061 | N18: =_xlfn.POISSON.DIST(3,($B$19*F18/'Monte Carlo'!$B$21),0) -> 0.052377166 | Q18: 1 | R18: 2 | S18: =AVERAGE($H$2:$H$1001)*AVERAGE($M$2:$M$1001) -> 0.040561254
